Workbook

Sheet 서식
A1: 보험구분 | B1: 성명 | C1: 주민(외국인)등록번호 | D1: 국적코드 | E1: 체류자격코드 | F1: 전화(지역번호) | G1: 전화(국번) | H1: 전화(뒷번호) | I1: 직종코드 | J1: 1일 | K1: 2일 | L1: 3일 | M1: 4일 | N1: 5일 | O1: 6일 | P1: 7일 | Q1: 8일 | R1: 9일 | S1: 10일 | T1: 11일 | U1: 12일 | V1: 13일 | W1: 14일 | X1: 15일 | Y1: 16일 | Z1: 17일 | AA1: 18일 | AB1: 19일 | AC1: 20일 | AD1: 21일 | AE1: 22일 | AF1: 23일 | AG1: 24일 | AH1: 25일 | AI1: 26일 | AJ1: 27일 | AK1: 28일 | AL1: 29일 | AM1: 30일 | AN1: 31일 | AO1: 근로일수 | AP1: 일평균 근로시간 | AQ1: 보수지급 기초일수 | AR1: 보수총액 (과세소득) | AS1: 임금총액 | AT1: 이직사유코드 | AU1: 보험료부과구분 부호 | AV1: 보험료부과구분 사유 | AW1: 국세청 일용근로소득 신고여부 | AX1: 지급월 | AY1: 총지급액 (과세소득) | AZ1: 비과세소득 | BA1: 소득세 | BB1: 지방소득세
A2: 3 | B2: ='[1]근무일표(자동화)'!B5 -> 서영란 | C2: =_xlfn.IFNA(VLOOKUP(B2,[1]일용주민번호!A:B,2,0),"") -> 7012242386126 | D2: =IF($B2="","","100") -> 100 | F2: =IF($B2="","","02") -> 02 | G2: =IF($B2="","","538") -> 538 | H2: =IF($B2="","","6933") -> 6933 | I2: =IF($B2="","","615") -> 615 | W2: 1 | X2: 1 | Y2: 1 | AO2: =IF($B2="","",COUNTIF(J2:AN2,"=1")) -> 3 | AP2: =IF($B2="","","10") -> 10 | AQ2: =AO2 -> 3 | AR2: 390090 | AS2: =AR2 -> 390090 | AT2: =IF($B2="","","3") -> 3 | AW2: =IF($B2="","","Y") -> Y | AX2: =TEXT(EDATE(TODAY(), -1), "yyyymm") -> 202602 | AY2: =AR2 -> 390090
A3: 3 | B3: ='[1]근무일표(자동화)'!B6 -> 남점숙 | C3: =_xlfn.IFNA(VLOOKUP(B3,[1]일용주민번호!A:B,2,0),"") -> 6008182684328 | D3: =IF($B3="","","100") -> 100 | F3: =IF($B3="","","02") -> 02 | G3: =IF($B3="","","538") -> 538 | H3: =IF($B3="","","6933") -> 6933 | I3: =IF($B3="","","615") -> 615 | J3: 1 | P3: 1 | Q3: 1 | S3: 1 | T3: 1 | U3: 1 | V3: 1 | W3: 1 | X3: 1 | Z3: 1 | AA3: 1 | AB3: 1 | AC3: 1 | AD3: 1 | AG3: 1 | AH3: 1 | AK3: 1 | AO3: =IF($B3="","",COUNTIF(J3:AN3,"=1")) -> 17 | AP3: =IF($B3="","","10") -> 10 | AQ3: =AO3 -> 17 | AR3: 2210510 | AS3: =AR3 -> 2210510 | AT3: =IF($B3="","","3") -> 3 | AW3: =IF($B3="","","Y") -> Y | AX3: =TEXT(EDATE(TODAY(), -1), "yyyymm") -> 202602 | AY3: =AR3 -> 2210510
A4: 3 | B4: ='[1]근무일표(자동화)'!B7 -> 윤숙정 | C4: =_xlfn.IFNA(VLOOKUP(B4,[1]일용주민번호!A:B,2,0),"") -> 7704032798615 | D4: =IF($B4="","","100") -> 100 | F4: =IF($B4="","","02") -> 02 | G4: =IF($B4="","","538") -> 538 | H4: =IF($B4="","","6933") -> 6933 | I4: =IF($B4="","","615") -> 615 | Y4: 1 | Z4: 1 | AA4: 1 | AO4: =IF($B4="","",COUNTIF(J4:AN4,"=1")) -> 3 | AP4: =IF($B4="","","10") -> 10 | AQ4: =AO4 -> 3 | AR4: 390090 | AS4: =AR4 -> 390090 | AT4: =IF($B4="","","3") -> 3 | AW4: =IF($B4="","","Y") -> Y | AX4: =TEXT(EDATE(TODAY(), -1), "yyyymm") -> 202602 | AY4: =AR4 -> 390090
A5: 3 | B5: ='[1]근무일표(자동화)'!B8 -> 황윤석 | C5: =_xlfn.IFNA(VLOOKUP(B5,[1]일용주민번호!A:B,2,0),"") -> 9512161303319 | D5: =IF($B5="","","100") -> 100 | F5: =IF($B5="","","02") -> 02 | G5: =IF($B5="","","538") -> 538 | H5: =IF($B5="","","6933") -> 6933 | I5: =IF($B5="","","615") -> 615 | X5: 1 | Y5: 1 | Z5: 1 | AA5: 1 | AO5: =IF($B5="","",COUNTIF(J5:AN5,"=1")) -> 4 | AP5: =IF($B5="","","10") -> 10 | AQ5: =AO5 -> 4 | AR5: 454080 | AS5: =AR5 -> 454080 | AT5: =IF($B5="","","3") -> 3 | AW5: =IF($B5="","","Y") -> Y | AX5: =TEXT(EDATE(TODAY(), -1), "yyyymm") -> 202602 | AY5: =AR5 -> 454080
A6: 3 | B6: ='[1]근무일표(자동화)'!B9 -> 문창순 | C6: =_xlfn.IFNA(VLOOKUP(B6,[1]일용주민번호!A:B,2,0),"") -> 5411242908214 | D6: =IF($B6="","","100") -> 100 | F6: =IF($B6="","","02") -> 02 | G6: =IF($B6="","","538") -> 538 | H6: =IF($B6="","","6933") -> 6933 | I6: =IF($B6="","","615") -> 615 | L6: 1 | N6: 1 | T6: 1 | U6: 1 | V6: 1 | AA6: 1 | AB6: 1 | AC6: 1 | AE6: 1 | AF6: 1 | AH6: 1 | AI6: 1 | AJ6: 1 | AK6: 1 | AO6: =IF($B6="","",COUNTIF(J6:AN6,"=1")) -> 14 | AP6: =IF($B6="","","10") -> 10 | AQ6: =AO6 -> 14 | AR6: 1647100 | AS6: =AR6 -> 1647100 | AT6: =IF($B6="","","3") -> 3 | AW6: =IF($B6="","","Y") -> Y | AX6: =TEXT(EDATE(TODAY(), -1), "yyyymm") -> 202602 | AY6: =AR6 -> 1647100
A7: 3 | B7: ='[1]근무일표(자동화)'!B10 -> 남정옥 | C7: =_xlfn.IFNA(VLOOKUP(B7,[1]일용주민번호!A:B,2,0),"") -> 5206042241317 | D7: =IF($B7="","","100") -> 100 | F7: =IF($B7="","","02") -> 02 | G7: =IF($B7="","","538") -> 538 | H7: =IF($B7="","","6933") -> 6933 | I7: =IF($B7="","","615") -> 615 | L7: 1 | P7: 1 | Q7: 1 | U7: 1 | AB7: 1 | AI7: 1 | AJ7: 1 | AK7: 1 | AO7: =IF($B7="","",COUNTIF(J7:AN7,"=1")) -> 8 | AP7: =IF($B7="","","10") -> 10 | AQ7: =AO7 -> 8 | AR7: 941200 | AS7: =AR7 -> 941200 | AT7: =IF($B7="","","3") -> 3 | AW7: =IF($B7="","","Y") -> Y | AX7: =TEXT(EDATE(TODAY(), -1), "yyyymm") -> 202602 | AY7: =AR7 -> 941200
A8: 3 | B8: ='[1]근무일표(자동화)'!B11 -> 강현승 | C8: =_xlfn.IFNA(VLOOKUP(B8,[1]일용주민번호!A:B,2,0),"") -> 0007093908212 | D8: =IF($B8="","","100") -> 100 | F8: =IF($B8="","","02") -> 02 | G8: =IF($B8="","","538") -> 538 | H8: =IF($B8="","","6933") -> 6933 | I8: =IF($B8="","","615") -> 615 | J8: 1 | M8: 1 | N8: 1 | R8: 1 | AO8: =IF($B8="","",COUNTIF(J8:AN8,"=1")) -> 4 | AP8: =IF($B8="","","10") -> 10 | AQ8: =AO8 -> 4 | AR8: 410000 | AS8: =AR8 -> 410000 | AT8: =IF($B8="","","3") -> 3 | AW8: =IF($B8="","","Y") -> Y | AX8: =TEXT(EDATE(TODAY(), -1), "yyyymm") -> 202602 | AY8: =AR8 -> 410000
A9: 3 | B9: ='[1]근무일표(자동화)'!B12 -> 임서진 | C9: =_xlfn.IFNA(VLOOKUP(B9,[1]일용주민번호!A:B,2,0),"") -> 0811143905913 | D9: =IF($B9="","","100") -> 100 | F9: =IF($B9="","","02") -> 02 | G9: =IF($B9="","","538") -> 538 | H9: =IF($B9="","","6933") -> 6933 | I9: =IF($B9="","","615") -> 615 | W9: 1 | X9: 1 | Y9: 1 | Z9: 1 | AA9: 1 | AO9: =IF($B9="","",COUNTIF(J9:AN9,"=1")) -> 5 | AP9: =IF($B9="","","10") -> 10 | AQ9: =AO9 -> 5 | AR9: 656000 | AS9: =AR9 -> 656000 | AT9: =IF($B9="","","3") -> 3 | AW9: =IF($B9="","","Y") -> Y | AX9: =TEXT(EDATE(TODAY(), -1), "yyyymm") -> 202602 | AY9: =AR9 -> 656000
A10: 3 | B10: ='[1]근무일표(자동화)'!B13 -> 황윤서 | C10: =_xlfn.IFNA(VLOOKUP(B10,[1]일용주민번호!A:B,2,0),"") -> 0403154684918 | D10: =IF($B10="","","100") -> 100 | F10: =IF($B10="","","02") -> 02 | G10: =IF($B10="","","538") -> 538 | H10: =IF($B10="","","6933") -> 6933 | I10: =IF($B10="","","615") -> 615 | W10: 1 | AO10: =IF($B10="","",COUNTIF(J10:AN10,"=1")) -> 1 | AP10: =IF($B10="","","10") -> 10 | AQ10: =AO10 -> 1 | AR10: 130030 | AS10: =AR10 -> 130030 | AT10: =IF($B10="","","3") -> 3 | AW10: =IF($B10="","","Y") -> Y | AX10: =TEXT(EDATE(TODAY(), -1), "yyyymm") -> 202602 | AY10: =AR10 -> 130030
A11: 3 | B11: ='[1]근무일표(자동화)'!B14 -> 서미란 | C11: =_xlfn.IFNA(VLOOKUP(B11,[1]일용주민번호!A:B,2,0),"") -> 5412092684210 | D11: =IF($B11="","","100") -> 100 | F11: =IF($B11="","","02") -> 02 | G11: =IF($B11="","","538") -> 538 | H11: =IF($B11="","","6933") -> 6933 | I11: =IF($B11="","","615") -> 615 | W11: 1 | X11: 1 | Y11: 1 | AO11: =IF($B11="","",COUNTIF(J11:AN11,"=1")) -> 3 | AP11: =IF($B11="","","10") -> 10 | AQ11: =AO11 -> 3 | AR11: 390090 | AS11: =AR11 -> 390090 | AT11: =IF($B11="","","3") -> 3 | AW11: =IF($B11="","","Y") -> Y | AX11: =TEXT(EDATE(TODAY(), -1), "yyyymm") -> 202602 | AY11: =AR11 -> 390090
A12: 3 | B12: ='[1]근무일표(자동화)'!B15 -> 김광훈 | C12: =_xlfn.IFNA(VLOOKUP(B12,[1]일용주민번호!A:B,2,0),"") -> 5910101773413 | D12: =IF($B12="","","100") -> 100 | F12: =IF($B12="","","02") -> 02 | G12: =IF($B12="","","538") -> 538 | H12: =IF($B12="","","6933") -> 6933 | I12: =IF($B12="","","615") -> 615 | L12: 1 | M12: 1 | S12: 1 | T12: 1 | Y12: 1 | Z12: 1 | AA12: 1 | AB12: 1 | AC12: 1 | AG12: 1 | AH12: 1 | AO12: =IF($B12="","",COUNTIF(J12:AN12,"=1")) -> 11 | AP12: =IF($B12="","","10") -> 10 | AQ12: =AO12 -> 11 | AR12: 1430330 | AS12: =AR12 -> 1430330 | AT12: =IF($B12="","","3") -> 3 | AW12: =IF($B12="","","Y") -> Y | AX12: =TEXT(EDATE(TODAY(), -1), "yyyymm") -> 202602 | AY12: =AR12 -> 1430330
A13: 3 | B13: ='[1]근무일표(자동화)'!B16 -> 장옥연 | C13: =_xlfn.IFNA(VLOOKUP(B13,[1]일용주민번호!A:B,2,0),"") -> 6102192322012 | D13: =IF($B13="","","100") -> 100 | F13: =IF($B13="","","02") -> 02 | G13: =IF($B13="","","538") -> 538 | H13: =IF($B13="","","6933") -> 6933 | I13: =IF($B13="","","615") -> 615 | AA13: 1 | AO13: =IF($B13="","",COUNTIF(J13:AN13,"=1")) -> 1 | AP13: =IF($B13="","","10") -> 10 | AQ13: =AO13 -> 1 | AR13: 117650 | AS13: =AR13 -> 117650 | AT13: =IF($B13="","","3") -> 3 | AW13: =IF($B13="","","Y") -> Y | AX13: =TEXT(EDATE(TODAY(), -1), "yyyymm") -> 202602 | AY13: =AR13 -> 117650
A14: 3 | B14: ='[1]근무일표(자동화)'!B17 -> 이성준 | C14: =_xlfn.IFNA(VLOOKUP(B14,[1]일용주민번호!A:B,2,0),"") -> 0312113798112 | D14: =IF($B14="","","100") -> 100 | F14: =IF($B14="","","02") -> 02 | G14: =IF($B14="","","538") -> 538 | H14: =IF($B14="","","6933") -> 6933 | I14: =IF($B14="","","615") -> 615 | W14: 1 | X14: 1 | Y14: 1 | Z14: 1 | AA14: 1 | AO14: =IF($B14="","",COUNTIF(J14:AN14,"=1")) -> 5 | AP14: =IF($B14="","","10") -> 10 | AQ14: =AO14 -> 5 | AR14: 650150 | AS14: =AR14 -> 650150 | AT14: =IF($B14="","","3") -> 3 | AW14: =IF($B14="","","Y") -> Y | AX14: =TEXT(EDATE(TODAY(), -1), "yyyymm") -> 202602 | AY14: =AR14 -> 650150
A15: 3 | B15: ='[1]근무일표(자동화)'!B18 -> 이양산 | C15: =_xlfn.IFNA(VLOOKUP(B15,[1]일용주민번호!A:B,2,0),"") -> 5702012908221 | D15: =IF($B15="","","100") -> 100 | F15: =IF($B15="","","02") -> 02 | G15: =IF($B15="","","538") -> 538 | H15: =IF($B15="","","6933") -> 6933 | I15: =IF($B15="","","615") -> 615 | J15: 1 | O15: 1 | P15: 1 | Q15: 1 | V15: 1 | AA15: 1 | AB15: 1 | AC15: 1 | AD15: 1 | AE15: 1 | AH15: 1 | AI15: 1 | AO15: =IF($B15="","",COUNTIF(J15:AN15,"=1")) -> 12 | AP15: =IF($B15="","","10") -> 10 | AQ15: =AO15 -> 12 | AR15: 1411800 | AS15: =AR15 -> 1411800 | AT15: =IF($B15="","","3") -> 3 | AW15: =IF($B15="","","Y") -> Y | AX15: =TEXT(EDATE(TODAY(), -1), "yyyymm") -> 202602 | AY15: =AR15 -> 1411800
A16: 3 | B16: ='[1]근무일표(자동화)'!B19 -> 정옥선 | C16: =_xlfn.IFNA(VLOOKUP(B16,[1]일용주민번호!A:B,2,0),"") -> 5912052235616 | D16: =IF($B16="","","100") -> 100 | F16: =IF($B16="","","02") -> 02 | G16: =IF($B16="","","538") -> 538 | H16: =IF($B16="","","6933") -> 6933 | I16: =IF($B16="","","615") -> 615 | J16: 1 | L16: 1 | M16: 1 | O16: 1 | S16: 1 | T16: 1 | U16: 1 | V16: 1 | AB16: 1 | AC16: 1 | AD16: 1 | AE16: 1 | AH16: 1 | AI16: 1 | AJ16: 1 | AK16: 1 | AO16: =IF($B16="","",COUNTIF(J16:AN16,"=1")) -> 16 | AP16: =IF($B16="","","10") -> 10 | AQ16: =AO16 -> 16 | AR16: 2080480 | AS16: =AR16 -> 2080480 | AT16: =IF($B16="","","3") -> 3 | AW16: =IF($B16="","","Y") -> Y | AX16: =TEXT(EDATE(TODAY(), -1), "yyyymm") -> 202602 | AY16: =AR16 -> 2080480
A17: 3 | B17: ='[1]근무일표(자동화)'!B20 -> 권기남 | C17: =_xlfn.IFNA(VLOOKUP(B17,[1]일용주민번호!A:B,2,0),"") -> 0310153902315 | D17: =IF($B17="","","100") -> 100 | F17: =IF($B17="","","02") -> 02 | G17: =IF($B17="","","538") -> 538 | H17: =IF($B17="","","6933") -> 6933 | I17: =IF($B17="","","615") -> 615 | K17: 1 | M17: 1 | O17: 1 | R17: 1 | S17: 1 | X17: 1 | Y17: 1 | Z17: 1 | AB17: 1 | AC17: 1 | AF17: 1 | AG17: 1 | AH17: 1 | AI17: 1 | AJ17: 1 | AO17: =IF($B17="","",COUNTIF(J17:AN17,"=1")) -> 15 | AP17: =IF($B17="","","10") -> 10 | AQ17: =AO17 -> 15 | AR17: 1646000 | AS17: =AR17 -> 1646000 | AT17: =IF($B17="","","3") -> 3 | AW17: =IF($B17="","","Y") -> Y | AX17: =TEXT(EDATE(TODAY(), -1), "yyyymm") -> 202602 | AY17: =AR17 -> 1646000
A18: 3 | B18: ='[1]근무일표(자동화)'!B21 -> 손보경 | C18: =_xlfn.IFNA(VLOOKUP(B18,[1]일용주민번호!A:B,2,0),"") -> 0912184861410 | D18: =IF($B18="","","100") -> 100 | F18: =IF($B18="","","02") -> 02 | G18: =IF($B18="","","538") -> 538 | H18: =IF($B18="","","6933") -> 6933 | I18: =IF($B18="","","615") -> 615 | W18: 1 | X18: 1 | Y18: 1 | Z18: 1 | AB18: 1 | AC18: 1 | AO18: =IF($B18="","",COUNTIF(J18:AN18,"=1")) -> 6 | AP18: =IF($B18="","","10") -> 10 | AQ18: =AO18 -> 6 | AR18: 640000 | AS18: =AR18 -> 640000 | AT18: =IF($B18="","","3") -> 3 | AW18: =IF($B18="","","Y") -> Y | AX18: =TEXT(EDATE(TODAY(), -1), "yyyymm") -> 202602 | AY18: =AR18 -> 640000
A19: 3 | B19: ='[1]근무일표(자동화)'!B22 -> 유도온 | C19: =_xlfn.IFNA(VLOOKUP(B19,[1]일용주민번호!A:B,2,0),"") -> 8509242852341 | D19: =IF($B19="","","100") -> 100 | F19: =IF($B19="","","02") -> 02 | G19: =IF($B19="","","538") -> 538 | H19: =IF($B19="","","6933") -> 6933 | I19: =IF($B19="","","615") -> 615 | W19: 1 | X19: 1 | Y19: 1 | AO19: =IF($B19="","",COUNTIF(J19:AN19,"=1")) -> 3 | AP19: =IF($B19="","","10") -> 10 | AQ19: =AO19 -> 3 | AR19: 393000 | AS19: =AR19 -> 393000 | AT19: =IF($B19="","","3") -> 3 | AW19: =IF($B19="","","Y") -> Y | AX19: =TEXT(EDATE(TODAY(), -1), "yyyymm") -> 202602 | AY19: =AR19 -> 393000
A20: 3 | B20: ='[1]근무일표(자동화)'!B23 -> 김미진 | C20: =_xlfn.IFNA(VLOOKUP(B20,[1]일용주민번호!A:B,2,0),"") -> 0103024693111 | D20: =IF($B20="","","100") -> 100 | F20: =IF($B20="","","02") -> 02 | G20: =IF($B20="","","538") -> 538 | H20: =IF($B20="","","6933") -> 6933 | I20: =IF($B20="","","615") -> 615 | J20: 1 | K20: 1 | L20: 1 | M20: 1 | Q20: 1 | R20: 1 | S20: 1 | T20: 1 | U20: 1 | W20: 1 | X20: 1 | Y20: 1 | Z20: 1 | AA20: 1 | AB20: 1 | AE20: 1 | AF20: 1 | AG20: 1 | AH20: 1 | AI20: 1 | AO20: =IF($B20="","",COUNTIF(J20:AN20,"=1")) -> 20 | AP20: =IF($B20="","","10") -> 10 | AQ20: =AO20 -> 20 | AR20: 2600600 | AS20: =AR20 -> 2600600 | AT20: =IF($B20="","","3") -> 3 | AW20: =IF($B20="","","Y") -> Y | AX20: =TEXT(EDATE(TODAY(), -1), "yyyymm") -> 202602 | AY20: =AR20 -> 2600600
A21: 3 | B21: ='[1]근무일표(자동화)'!B24 -> 강정분 | C21: =_xlfn.IFNA(VLOOKUP(B21,[1]일용주민번호!A:B,2,0),"") -> 5104202922915 | D21: =IF($B21="","","100") -> 100 | F21: =IF($B21="","","02") -> 02 | G21: =IF($B21="","","538") -> 538 | H21: =IF($B21="","","6933") -> 6933 | I21: =IF($B21="","","615") -> 615 | J21: 1 | O21: 1 | AO21: =IF($B21="","",COUNTIF(J21:AN21,"=1")) -> 2 | AP21: =IF($B21="","","10") -> 10 | AQ21: =AO21 -> 2 | AR21: 235300 | AS21: =AR21 -> 235300 | AT21: =IF($B21="","","3") -> 3 | AW21: =IF($B21="","","Y") -> Y | AX21: =TEXT(EDATE(TODAY(), -1), "yyyymm") -> 202602 | AY21: =AR21 -> 235300
A22: 3 | B22: ='[1]근무일표(자동화)'!B25 -> 정건아 | C22: =_xlfn.IFNA(VLOOKUP(B22,[1]일용주민번호!A:B,2,0),"") -> 0103243697818 | D22: =IF($B22="","","100") -> 100 | F22: =IF($B22="","","02") -> 02 | G22: =IF($B22="","","538") -> 538 | H22: =IF($B22="","","6933") -> 6933 | I22: =IF($B22="","","615") -> 615 | Y22: 1 | Z22: 1 | AO22: =IF($B22="","",COUNTIF(J22:AN22,"=1")) -> 2 | AP22: =IF($B22="","","10") -> 10 | AQ22: =AO22 -> 2 | AR22: 260060 | AS22: =AR22 -> 260060 | AT22: =IF($B22="","","3") -> 3 | AW22: =IF($B22="","","Y") -> Y | AX22: =TEXT(EDATE(TODAY(), -1), "yyyymm") -> 202602 | AY22: =AR22 -> 260060
A23: 3 | B23: ='[1]근무일표(자동화)'!B26 -> 정춘희 | C23: =_xlfn.IFNA(VLOOKUP(B23,[1]일용주민번호!A:B,2,0),"") -> 8303192348511 | D23: =IF($B23="","","100") -> 100 | F23: =IF($B23="","","02") -> 02 | G23: =IF($B23="","","538") -> 538 | H23: =IF($B23="","","6933") -> 6933 | I23: =IF($B23="","","615") -> 615 | K23: 1 | L23: 1 | M23: 1 | P23: 1 | Q23: 1 | R23: 1 | S23: 1 | Y23: 1 | Z23: 1 | AA23: 1 | AB23: 1 | AD23: 1 | AE23: 1 | AF23: 1 | AG23: 1 | AH23: 1 | AI23: 1 | AJ23: 1 | AO23: =IF($B23="","",COUNTIF(J23:AN23,"=1")) -> 18 | AP23: =IF($B23="","","10") -> 10 | AQ23: =AO23 -> 18 | AR23: 2356020 | AS23: =AR23 -> 2356020 | AT23: =IF($B23="","","3") -> 3 | AW23: =IF($B23="","","Y") -> Y | AX23: =TEXT(EDATE(TODAY(), -1), "yyyymm") -> 202602 | AY23: =AR23 -> 2356020
A24: 3 | B24: ='[1]근무일표(자동화)'!B27 -> 임정현 | C24: =_xlfn.IFNA(VLOOKUP(B24,[1]일용주민번호!A:B,2,0),"") -> 0701013803229 | D24: =IF($B24="","","100") -> 100 | F24: =IF($B24="","","02") -> 02 | G24: =IF($B24="","","538") -> 538 | H24: =IF($B24="","","6933") -> 6933 | I24: =IF($B24="","","615") -> 615 | W24: 1 | X24: 1 | Z24: 1 | AO24: =IF($B24="","",COUNTIF(J24:AN24,"=1")) -> 3 | AP24: =IF($B24="","","10") -> 10 | AQ24: =AO24 -> 3 | AR24: 483180 | AS24: =AR24 -> 483180 | AT24: =IF($B24="","","3") -> 3 | AW24: =IF($B24="","","Y") -> Y | AX24: =TEXT(EDATE(TODAY(), -1), "yyyymm") -> 202602 | AY24: =AR24 -> 483180
A25: 3 | B25: ='[1]근무일표(자동화)'!B28 -> 조용조 | C25: =_xlfn.IFNA(VLOOKUP(B25,[1]일용주민번호!A:B,2,0),"") -> 9210161698119 | D25: =IF($B25="","","100") -> 100 | F25: =IF($B25="","","02") -> 02 | G25: =IF($B25="","","538") -> 538 | H25: =IF($B25="","","6933") -> 6933 | I25: =IF($B25="","","615") -> 615 | X25: 1 | Y25: 1 | Z25: 1 | AA25: 1 | AO25: =IF($B25="","",COUNTIF(J25:AN25,"=1")) -> 4 | AP25: =IF($B25="","","10") -> 10 | AQ25: =AO25 -> 4 | AR25: 520120 | AS25: =AR25 -> 520120 | AT25: =IF($B25="","","3") -> 3 | AW25: =IF($B25="","","Y") -> Y | AX25: =TEXT(EDATE(TODAY(), -1), "yyyymm") -> 202602 | AY25: =AR25 -> 520120
A26: 3 | B26: ='[1]근무일표(자동화)'!B29 -> 용재선 | C26: =_xlfn.IFNA(VLOOKUP(B26,[1]일용주민번호!A:B,2,0),"") -> 6509102927612 | D26: =IF($B26="","","100") -> 100 | F26: =IF($B26="","","02") -> 02 | G26: =IF($B26="","","538") -> 538 | H26: =IF($B26="","","6933") -> 6933 | I26: =IF($B26="","","615") -> 615 | K26: 1 | L26: 1 | M26: 1 | N26: 1 | P26: 1 | Q26: 1 | R26: 1 | S26: 1 | T26: 1 | W26: 1 | X26: 1 | Y26: 1 | Z26: 1 | AA26: 1 | AB26: 1 | AC26: 1 | AF26: 1 | AG26: 1 | AH26: 1 | AI26: 1 | AO26: =IF($B26="","",COUNTIF(J26:AN26,"=1")) -> 20 | AP26: =IF($B26="","","10") -> 10 | AQ26: =AO26 -> 20 | AR26: 2600600 | AS26: =AR26 -> 2600600 | AT26: =IF($B26="","","3") -> 3 | AW26: =IF($B26="","","Y") -> Y | AX26: =TEXT(EDATE(TODAY(), -1), "yyyymm") -> 202602 | AY26: =AR26 -> 2600600
A27: 3 | B27: ='[1]근무일표(자동화)'!B30 -> 이재민 | C27: =_xlfn.IFNA(VLOOKUP(B27,[1]일용주민번호!A:B,2,0),"") -> 0404243784016 | D27: =IF($B27="","","100") -> 100 | F27: =IF($B27="","","02") -> 02 | G27: =IF($B27="","","538") -> 538 | H27: =IF($B27="","","6933") -> 6933 | I27: =IF($B27="","","615") -> 615 | K27: 1 | L27: 1 | O27: 1 | Q27: 1 | T27: 1 | U27: 1 | W27: 1 | X27: 1 | AA27: 1 | AB27: 1 | AD27: 1 | AE27: 1 | AF27: 1 | AG27: 1 | AH27: 1 | AI27: 1 | AJ27: 1 | AK27: 1 | AO27: =IF($B27="","",COUNTIF(J27:AN27,"=1")) -> 18 | AP27: =IF($B27="","","10") -> 10 | AQ27: =AO27 -> 18 | AR27: 1830000 | AS27: =AR27 -> 1830000 | AT27: =IF($B27="","","3") -> 3 | AW27: =IF($B27="","","Y") -> Y | AX27: =TEXT(EDATE(TODAY(), -1), "yyyymm") -> 202602 | AY27: =AR27 -> 1830000
A28: 3 | B28: ='[1]근무일표(자동화)'!B31 -> 김혜성 | C28: =_xlfn.IFNA(VLOOKUP(B28,[1]일용주민번호!A:B,2,0),"") -> 7408292696311 | D28: =IF($B28="","","100") -> 100 | F28: =IF($B28="","","02") -> 02 | G28: =IF($B28="","","538") -> 538 | H28: =IF($B28="","","6933") -> 6933 | I28: =IF($B28="","","615") -> 615 | W28: 1 | X28: 1 | AA28: 1 | AB28: 1 | AO28: =IF($B28="","",COUNTIF(J28:AN28,"=1")) -> 4 | AP28: =IF($B28="","","10") -> 10 | AQ28: =AO28 -> 4 | AR28: 390200 | AS28: =AR28 -> 390200 | AT28: =IF($B28="","","3") -> 3 | AW28: =IF($B28="","","Y") -> Y | AX28: =TEXT(EDATE(TODAY(), -1), "yyyymm") -> 202602 | AY28: =AR28 -> 390200
A29: 3 | B29: ='[1]근무일표(자동화)'!B32 -> 백한순 | C29: =_xlfn.IFNA(VLOOKUP(B29,[1]일용주민번호!A:B,2,0),"") -> 0009274853322 | D29: =IF($B29="","","100") -> 100 | F29: =IF($B29="","","02") -> 02 | G29: =IF($B29="","","538") -> 538 | H29: =IF($B29="","","6933") -> 6933 | I29: =IF($B29="","","615") -> 615 | L29: 1 | M29: 1 | N29: 1 | P29: 1 | Q29: 1 | R29: 1 | S29: 1 | V29: 1 | W29: 1 | X29: 1 | Y29: 1 | Z29: 1 | AA29: 1 | AD29: 1 | AE29: 1 | AF29: 1 | AG29: 1 | AJ29: 1 | AK29: 1 | AO29: =IF($B29="","",COUNTIF(J29:AN29,"=1")) -> 19 | AP29: =IF($B29="","","10") -> 10 | AQ29: =AO29 -> 19 | AR29: 3198070 | AS29: =AR29 -> 3198070 | AT29: =IF($B29="","","3") -> 3 | AW29: =IF($B29="","","Y") -> Y | AX29: =TEXT(EDATE(TODAY(), -1), "yyyymm") -> 202602 | AY29: =AR29 -> 3198070
A30: 3 | B30: ='[1]근무일표(자동화)'!B33 -> 권귀현 | C30: =_xlfn.IFNA(VLOOKUP(B30,[1]일용주민번호!A:B,2,0),"") -> 0704234902310 | D30: =IF($B30="","","100") -> 100 | F30: =IF($B30="","","02") -> 02 | G30: =IF($B30="","","538") -> 538 | H30: =IF($B30="","","6933") -> 6933 | I30: =IF($B30="","","615") -> 615 | L30: 1 | N30: 1 | T30: 1 | U30: 1 | X30: 1 | Y30: 1 | Z30: 1 | AO30: =IF($B30="","",COUNTIF(J30:AN30,"=1")) -> 7 | AP30: =IF($B30="","","10") -> 10 | AQ30: =AO30 -> 7 | AR30: 913220 | AS30: =AR30 -> 913220 | AT30: =IF($B30="","","3") -> 3 | AW30: =IF($B30="","","Y") -> Y | AX30: =TEXT(EDATE(TODAY(), -1), "yyyymm") -> 202602 | AY30: =AR30 -> 913220
A31: 3 | B31: ='[1]근무일표(자동화)'!B34 -> 조보람 | C31: =_xlfn.IFNA(VLOOKUP(B31,[1]일용주민번호!A:B,2,0),"") -> 9503152200612 | D31: =IF($B31="","","100") -> 100 | F31: =IF($B31="","","02") -> 02 | G31: =IF($B31="","","538") -> 538 | H31: =IF($B31="","","6933") -> 6933 | I31: =IF($B31="","","615") -> 615 | K31: 1 | L31: 1 | M31: 1 | N31: 1 | O31: 1 | R31: 1 | S31: 1 | T31: 1 | U31: 1 | X31: 1 | Y31: 1 | Z31: 1 | AA31: 1 | AB31: 1 | AC31: 1 | AF31: 1 | AG31: 1 | AH31: 1 | AI31: 1 | AJ31: 1 | AO31: =IF($B31="","",COUNTIF(J31:AN31,"=1")) -> 20 | AP31: =IF($B31="","","10") -> 10 | AQ31: =AO31 -> 20 | AR31: 3328100 | AS31: =AR31 -> 3328100 | AT31: =IF($B31="","","3") -> 3 | AW31: =IF($B31="","","Y") -> Y | AX31: =TEXT(EDATE(TODAY(), -1), "yyyymm") -> 202602 | AY31: =AR31 -> 3328100
A32: 3 | B32: ='[1]근무일표(자동화)'!B35 -> 최경희 | C32: =_xlfn.IFNA(VLOOKUP(B32,[1]일용주민번호!A:B,2,0),"") -> 6809212820417 | D32: =IF($B32="","","100") -> 100 | F32: =IF($B32="","","02") -> 02 | G32: =IF($B32="","","538") -> 538 | H32: =IF($B32="","","6933") -> 6933 | I32: =IF($B32="","","615") -> 615 | W32: 1 | X32: 1 | Y32: 1 | Z32: 1 | AO32: =IF($B32="","",COUNTIF(J32:AN32,"=1")) -> 4 | AP32: =IF($B32="","","10") -> 10 | AQ32: =AO32 -> 4 | AR32: 440000 | AS32: =AR32 -> 440000 | AT32: =IF($B32="","","3") -> 3 | AW32: =IF($B32="","","Y") -> Y | AX32: =TEXT(EDATE(TODAY(), -1), "yyyymm") -> 202602 | AY32: =AR32 -> 440000
A33: 3 | B33: ='[1]근무일표(자동화)'!B36 -> 정세영 | C33: =_xlfn.IFNA(VLOOKUP(B33,[1]일용주민번호!A:B,2,0),"") -> 8702261910214 | D33: =IF($B33="","","100") -> 100 | F33: =IF($B33="","","02") -> 02 | G33: =IF($B33="","","538") -> 538 | H33: =IF($B33="","","6933") -> 6933 | I33: =IF($B33="","","615") -> 615 | X33: 1 | Y33: 1 | Z33: 1 | AA33: 1 | AO33: =IF($B33="","",COUNTIF(J33:AN33,"=1")) -> 4 | AP33: =IF($B33="","","10") -> 10 | AQ33: =AO33 -> 4 | AR33: 400000 | AS33: =AR33 -> 400000 | AT33: =IF($B33="","","3") -> 3 | AW33: =IF($B33="","","Y") -> Y | AX33: =TEXT(EDATE(TODAY(), -1), "yyyymm") -> 202602 | AY33: =AR33 -> 400000
A34: 3 | B34: ='[1]근무일표(자동화)'!B37 -> 구한길 | C34: =_xlfn.IFNA(VLOOKUP(B34,[1]일용주민번호!A:B,2,0),"") -> 8509211891915 | D34: =IF($B34="","","100") -> 100 | F34: =IF($B34="","","02") -> 02 | G34: =IF($B34="","","538") -> 538 | H34: =IF($B34="","","6933") -> 6933 | I34: =IF($B34="","","615") -> 615 | X34: 1 | Y34: 1 | Z34: 1 | AA34: 1 | AO34: =IF($B34="","",COUNTIF(J34:AN34,"=1")) -> 4 | AP34: =IF($B34="","","10") -> 10 | AQ34: =AO34 -> 4 | AR34: 400000 | AS34: =AR34 -> 400000 | AT34: =IF($B34="","","3") -> 3 | AW34: =IF($B34="","","Y") -> Y | AX34: =TEXT(EDATE(TODAY(), -1), "yyyymm") -> 202602 | AY34: =AR34 -> 400000
A35: 3 | B35: ='[1]근무일표(자동화)'!B38 -> 오대현 | C35: =_xlfn.IFNA(VLOOKUP(B35,[1]일용주민번호!A:B,2,0),"") -> 0404123109020 | D35: =IF($B35="","","100") -> 100 | F35: =IF($B35="","","02") -> 02 | G35: =IF($B35="","","538") -> 538 | H35: =IF($B35="","","6933") -> 6933 | I35: =IF($B35="","","615") -> 615 | W35: 1 | X35: 1 | AO35: =IF($B35="","",COUNTIF(J35:AN35,"=1")) -> 2 | AP35: =IF($B35="","","10") -> 10 | AQ35: =AO35 -> 2 | AR35: 262000 | AS35: =AR35 -> 262000 | AT35: =IF($B35="","","3") -> 3 | AW35: =IF($B35="","","Y") -> Y | AX35: =TEXT(EDATE(TODAY(), -1), "yyyymm") -> 202602 | AY35: =AR35 -> 262000
A36: 3 | B36: ='[1]근무일표(자동화)'!B39 -> 최연재 | C36: =_xlfn.IFNA(VLOOKUP(B36,[1]일용주민번호!A:B,2,0),"") -> 9301132690910 | D36: =IF($B36="","","100") -> 100 | F36: =IF($B36="","","02") -> 02 | G36: =IF($B36="","","538") -> 538 | H36: =IF($B36="","","6933") -> 6933 | I36: =IF($B36="","","615") -> 615 | W36: 1 | X36: 1 | Y36: 1 | Z36: 1 | AO36: =IF($B36="","",COUNTIF(J36:AN36,"=1")) -> 4 | AP36: =IF($B36="","","10") -> 10 | AQ36: =AO36 -> 4 | AR36: 524000 | AS36: =AR36 -> 524000 | AT36: =IF($B36="","","3") -> 3 | AW36: =IF($B36="","","Y") -> Y | AX36: =TEXT(EDATE(TODAY(), -1), "yyyymm") -> 202602 | AY36: =AR36 -> 524000
A37: 3 | B37: ='[1]근무일표(자동화)'!B40 -> 정나경 | C37: =_xlfn.IFNA(VLOOKUP(B37,[1]일용주민번호!A:B,2,0),"") -> 0402264823715 | D37: =IF($B37="","","100") -> 100 | F37: =IF($B37="","","02") -> 02 | G37: =IF($B37="","","538") -> 538 | H37: =IF($B37="","","6933") -> 6933 | I37: =IF($B37="","","615") -> 615 | J37: 1 | P37: 1 | Q37: 1 | W37: 1 | X37: 1 | Y37: 1 | Z37: 1 | AA37: 1 | AD37: 1 | AE37: 1 | AK37: 1 | AO37: =IF($B37="","",COUNTIF(J37:AN37,"=1")) -> 11 | AP37: =IF($B37="","","10") -> 10 | AQ37: =AO37 -> 11 | AR37: 1210000 | AS37: =AR37 -> 1210000 | AT37: =IF($B37="","","3") -> 3 | AW37: =IF($B37="","","Y") -> Y | AX37: =TEXT(EDATE(TODAY(), -1), "yyyymm") -> 202602 | AY37: =AR37 -> 1210000
A38: 3 | B38: ='[1]근무일표(자동화)'!B41 -> 김강민 | C38: =_xlfn.IFNA(VLOOKUP(B38,[1]일용주민번호!A:B,2,0),"") -> 0204033854133 | D38: =IF($B38="","","100") -> 100 | F38: =IF($B38="","","02") -> 02 | G38: =IF($B38="","","538") -> 538 | H38: =IF($B38="","","6933") -> 6933 | I38: =IF($B38="","","615") -> 615 | K38: 1 | L38: 1 | V38: 1 | Y38: 1 | Z38: 1 | AA38: 1 | AF38: 1 | AG38: 1 | AO38: =IF($B38="","",COUNTIF(J38:AN38,"=1")) -> 8 | AP38: =IF($B38="","","10") -> 10 | AQ38: =AO38 -> 8 | AR38: 830000 | AS38: =AR38 -> 830000 | AT38: =IF($B38="","","3") -> 3 | AW38: =IF($B38="","","Y") -> Y | AX38: =TEXT(EDATE(TODAY(), -1), "yyyymm") -> 202602 | AY38: =AR38 -> 830000
A39: 3 | B39: ='[1]근무일표(자동화)'!B42 -> 박지언 | C39: =_xlfn.IFNA(VLOOKUP(B39,[1]일용주민번호!A:B,2,0),"") -> 1009203902214 | D39: =IF($B39="","","100") -> 100 | F39: =IF($B39="","","02") -> 02 | G39: =IF($B39="","","538") -> 538 | H39: =IF($B39="","","6933") -> 6933 | I39: =IF($B39="","","615") -> 615 | X39: 1 | Y39: 1 | Z39: 1 | AO39: =IF($B39="","",COUNTIF(J39:AN39,"=1")) -> 3 | AP39: =IF($B39="","","10") -> 10 | AQ39: =AO39 -> 3 | AR39: 262440 | AS39: =AR39 -> 262440 | AT39: =IF($B39="","","3") -> 3 | AW39: =IF($B39="","","Y") -> Y | AX39: =TEXT(EDATE(TODAY(), -1), "yyyymm") -> 202602 | AY39: =AR39 -> 262440
A40: 3 | B40: ='[1]근무일표(자동화)'!B43 -> 최영석 | C40: =_xlfn.IFNA(VLOOKUP(B40,[1]일용주민번호!A:B,2,0),"") -> 9602231096425 | D40: =IF($B40="","","100") -> 100 | F40: =IF($B40="","","02") -> 02 | G40: =IF($B40="","","538") -> 538 | H40: =IF($B40="","","6933") -> 6933 | I40: =IF($B40="","","615") -> 615 | X40: 1 | Y40: 1 | Z40: 1 | AO40: =IF($B40="","",COUNTIF(J40:AN40,"=1")) -> 3 | AP40: =IF($B40="","","10") -> 10 | AQ40: =AO40 -> 3 | AR40: 393000 | AS40: =AR40 -> 393000 | AT40: =IF($B40="","","3") -> 3 | AW40: =IF($B40="","","Y") -> Y | AX40: =TEXT(EDATE(TODAY(), -1), "yyyymm") -> 202602 | AY40: =AR40 -> 393000
...

Sheet 작성방법
A1: <작성법> 근로내용확인신고서
A3: 1 | B3: 보험구분 | C3: 고용보험, 산재보험 구분 - 1 : 산재보험 - 3 : 고용보험 - 5 : 산재,고용보험 * 보험구분이 1번인 경우(산재보험만 신고하는 경우) : 음영 표시된 항목만 작성하시기 바랍니다. * 토탈서비스 이용이 아닌 전자매체신고(CD)의 경우 산재보험만 신고 가능합니다.
A4: 2 | B4: 성명 | C4: 주민등록표(외국인등록증 또는 국내거소신고증)상의 성명를 적습니다.
A5: 3 | B5: 주민(외국인)등록번호 | C5: 13자리 숫자만 적습니다.("-" 제외)
A6: 4 | B6: 국적코드 | C6: 근로자의 국적코드 (국적코드표 참조)
A7: 5 | B7: 체류자격코드 | C7: 체류자격코드 시트 참조("-" 제외)
A8: 6 | B8: 전화(지역번호) | C8: 지역번호 (휴대폰의 경우 01x)
A9: 7 | B9: 전화(국번) | C9: 국번
A10: 8 | B10: 전화(뒷번호) | C10: 전화번호 뒷자리
A11: 9 | B11: 직종코드 | C11: 한국고용직업분류(KECO, 2025) 중 소분류(140개) 직종현황 참고하여 기재
A12: 10 | B12: 1~31일 | C12: 근로한 날짜에 "1" 기재
A13: 11 | B13: 근로일수 | C13: 한달간 근로한 일 수
A14: 12 | B14: 일평균근로시간 | C14: 일평균근로시간
... A20: 18 | B20: 보험료 부과구분 사유 (해당자만 기재) | C20: 보험료 부과구분 부호를 참고하여 해당자만 기재
A21: 19 | B21: 국세청 일용근로소득 신고여부 | C21: 신고시 Y 기재 | D21: "지급월" 항목이 기재되지 않으면 국세청으로 전송되지 않습니다. (나머지 항목은 미기재시 0원신고로 전송됨에 유의)
A22: 20 | B22: 총지급액(과세소득) | C22: 일용근로자에게 지급한 급여액(비과세소득 제외)의 월별 합계금액을 적습니다.
A23: 21 | B23: 지급월 | C23: "지급월"은 일용근로자에게 급여를 지급한 월(12월 말일까지 미지급한 금액은 12월)을 적습니다.
A24: 22 | B24: 비과세소득 (해당자만 기재) | C24: 생산직 일용근로자에게 지급한 야간근로수당 등 비과세소득의 해당 월의 합계금액
A25: 23 | B25: 소득세 (해당자만 기재) | C25: [근로소득금액×원천징수세율(6%)]-세액공제(산출세액의 55%)를 적용하여 계산한 해당 월의 금액 이 경우 근로소득금액은 1일 급여액에서 1일 10만원을 공제한 금액의 합계
A26: 24 | B26: 지방소득세 (해당자만 기재) | C26: 소득세의 10%
A27: ※ 21 ~ 25 항목에 대한 궁금한 사항은 국세청(국번없이 126번)으로 문의하시기 바랍니다.

Sheet 작성예시
A1: 보험구분 | B1: 성명 | C1: 주민(외국인)등록번호 | D1: 국적코드 | E1: 체류자격코드 | F1: 전화(지역번호) | G1: 전화(국번) | H1: 전화(뒷번호) | I1: 직종코드 | J1: 1일 | K1: 2일 | L1: 3일 | M1: 4일 | N1: 5일 | O1: 6일 | P1: 7일 | Q1: 8일 | R1: 9일 | S1: 10일 | T1: 11일 | U1: 12일 | V1: 13일 | W1: 14일 | X1: 15일 | Y1: 16일 | Z1: 17일 | AA1: 18일 | AB1: 19일 | AC1: 20일 | AD1: 21일 | AE1: 22일 | AF1: 23일 | AG1: 24일 | AH1: 25일 | AI1: 26일 | AJ1: 27일 | AK1: 28일 | AL1: 29일 | AM1: 30일 | AN1: 31일 | AO1: 근로일수 | AP1: 일평균근로시간 | AQ1: 보수지급기초일수 | AR1: 보수총액 | AS1: 임금총액 | AT1: 이직사유코드 | AU1: 보험료부과구분 부호 | AV1: 보험료부과구분 사유 | AW1: 국세청 일용근로소득 신고여부 | AX1: 지급월 | AY1: 총지급액(과세소득) | AZ1: 비과세소득 | BA1: 소득세 | BB1: 지방소득세
A2: 1 | B2: 홍길동1 | C2: 7801015555561 | D2: 100 | E2: A1 | F2: 010 | G2: 1111 | H2: 1111 | I2: 013 | J2: 1 | AD2: 1 | AO2: 2 | AP2: 8 | AQ2: 2 | AR2: 1000000 | AS2: 1000000 | AT2: 1 | AU2: 51 | AV2: 09
A3: 5 | B3: 홍길동2 | C3: 7801015555562 | D3: 100 | E3: A1 | F3: 010 | G3: 1111 | H3: 1111 | I3: 013 | P3: 1 | Z3: 1 | AO3: 2 | AP3: 8 | AQ3: 2 | AR3: 1000000 | AS3: 1000000 | AT3: 1 | AW3: Y | AX3: 202504 | AY3: 1000000
A4: 5 | B4: 홍길동3 | C4: 7801015555563 | D4: 100 | E4: A1 | F4: 010 | G4: 1111 | H4: 1111 | I4: 013 | M4: 1 | AA4: 1 | AE4: 1 | AO4: 3 | AP4: 8 | AQ4: 3 | AR4: 1000000 | AS4: 1000000 | AT4: 1
A5: 5 | B5: 홍길동4 | C5: 7801015555564 | D5: 100 | E5: A1 | F5: 010 | G5: 1111 | H5: 1111 | I5: 013 | O5: 1 | AJ5: 1 | AO5: 2 | AP5: 8 | AQ5: 2 | AR5: 1000000 | AS5: 1000000 | AT5: 1
A6: 5 | B6: 홍길동5 | C6: 7801015555565 | D6: 100 | E6: A1 | F6: 010 | G6: 1111 | H6: 1111 | I6: 013 | L6: 1 | AD6: 1 | AO6: 2 | AP6: 8 | AQ6: 2 | AR6: 1000000 | AS6: 1000000 | AT6: 1 | AU6: 57 | AV6: 14
A7: 5 | B7: 홍길동6 | C7: 7801015555566 | D7: 100 | E7: A1 | F7: 010 | G7: 1111 | H7: 1111 | I7: 013 | P7: 1 | AF7: 1 | AO7: 2 | AP7: 8 | AQ7: 2 | AR7: 1000000 | AS7: 1000000 | AT7: 1
A8: 5 | B8: 홍길동7 | C8: 7801015555567 | D8: 100 | E8: A1 | F8: 010 | G8: 1111 | H8: 1111 | I8: 013 | M8: 1 | O8: 1 | Z8: 1 | AJ8: 1 | AO8: 4 | AP8: 8 | AQ8: 4 | AR8: 1000000 | AS8: 1000000 | AT8: 1 | AW8: Y | AX8: 202504 | AY8: 1000000
A9: 5 | B9: 홍길동8 | C9: 7801015555568 | D9: 100 | E9: A1 | F9: 010 | G9: 1111 | H9: 1111 | I9: 013 | M9: 1 | P9: 1 | AO9: 2 | AP9: 8 | AQ9: 2 | AR9: 1000000 | AS9: 1000000 | AT9: 1
A10: 5 | B10: 홍길동9 | C10: 7801015555569 | D10: 100 | E10: A1 | F10: 010 | G10: 1111 | H10: 1111 | I10: 013 | AA10: 1 | AC10: 1 | AO10: 2 | AP10: 8 | AQ10: 2 | AR10: 1000000 | AS10: 1000000 | AT10: 1
A11: 3 | B11: 홍길동10 | C11: 7801015555570 | D11: 100 | E11: A1 | F11: 010 | G11: 1111 | H11: 1111 | I11: 013 | L11: 1 | P11: 1 | T11: 1 | AH11: 1 | AO11: 4 | AP11: 8 | AQ11: 4 | AR11: 1000000 | AS11: 1000000 | AT11: 1 | AU11: 56 | AV11: 01

Sheet 국적, 직종, 보험료부과구분코드
A1: 국적, 직종, 보험료부과구분코드 조회
A2: 고용/산재보험 직종 : | B2: http://www.4insure.or.kr/pbiz/cmmn/selectComCdList.do?comCdClsfId=D108
A3: 고용/산재보험 보험료부과구분 : | B3: http://www.4insure.or.kr/pbiz/cmmn/selectComCdList.do?comCdClsfId=C201
A4: 국적 : | B4: http://www.4insure.or.kr/pbiz/cmmn/selectComCdList.do?comCdClsfId=A151

Sheet 체류자격
A1: 체류자격
A3: 체류자격코드 | B3: 체류자격명 | C3: 체류자격설명
A4: 0-0 | B4: 체류자격없음 | C4: 체류자격없음
A5: A-1 | B5: 외교 | C5: 외교
A6: A-2 | B6: 공무 | C6: 공무
A7: A-3-1 | B7: 미군현역 | C7: 주한미군(현역및예비역)
A8: A-3-2 | B8: 미군군속 | C8: 주한미군군속,초청계약자,가족
A9: A-3-99 | B9: 기타협정 | C9: 기타협정
A10: B-1 | B10: 사증면제 | C10: 사증면제
A11: B-2-1 | B11: 일반무사증 | C11: 일반무사증입국
A12: B-2-2 | B12: 제주무사증 | C12: 제주무사증입국
A13: C-1 | B13: 일시취재 | C13: 일시취재
A14: C-2-1 | B14: 단기상용 | C14: 단기상용
... A237: T-1-1 | B237: 관광상륙 | C237: 선박도착관광상륙허가자

Sheet Sheet1
A2: 보험구분
A3: 코드 | B3: 내용
A4: 1 | B4: 산재보험
A5: 3 | B5: 고용보험
A6: 5 | B6: 산재 및 고용보험
A8: 이직사유
A9: 코드 | B9: 내용
A10: 1 | B10: 회사의 사정에 의한 이직 - 폐업, 공사중단, 공사종료, 계약기간 만료 등
A11: 2 | B11: 부득이한 개인 사정에 의한 이직 - 질병, 부상, 출산 등
A12: 3 | B12: 기타 개인사정에 의한 이직 - 전직, 자영업을 위한 이직 등
